import React from 'react';
import { render, screen } from '@testing-library/react';
import userEvent from '@testing-library/user-event';
import { ErrorBoundary } from '../../src/components/ErrorBoundary';

// Component that throws an error
const ThrowError = ({ shouldThrow }: { shouldThrow: boolean }) => {
  if (shouldThrow) {
    throw new Error('Test error');
  }
  return <div>Component rendered successfully</div>;
};

describe('ErrorBoundary', () => {
  // Suppress console.error for these tests
  const originalError = console.error;
  beforeAll(() => {
    console.error = jest.fn();
  });

  afterAll(() => {
    console.error = originalError;
  });

  it('should render children when there is no error', () => {
    render(
      <ErrorBoundary>
        <ThrowError shouldThrow={false} />
      </ErrorBoundary>
    );

    expect(screen.getByText('Component rendered successfully')).toBeInTheDocument();
  });

  it('should render error UI when there is an error', () => {
    render(
      <ErrorBoundary>
        <ThrowError shouldThrow={true} />
      </ErrorBoundary>
    );

    expect(screen.getByText('Something went wrong')).toBeInTheDocument();
    expect(
      screen.getByText('An error occurred while rendering this component.')
    ).toBeInTheDocument();
    expect(screen.getByRole('button', { name: 'Try Again' })).toBeInTheDocument();
  });

  it('should render custom fallback when provided', () => {
    const customFallback = <div>Custom error message</div>;

    render(
      <ErrorBoundary fallback={customFallback}>
        <ThrowError shouldThrow={true} />
      </ErrorBoundary>
    );

    expect(screen.getByText('Custom error message')).toBeInTheDocument();
  });

  it('should show try again button when error occurs', async () => {
    const user = userEvent.setup();

    render(
      <ErrorBoundary>
        <ThrowError shouldThrow={true} />
      </ErrorBoundary>
    );

    expect(screen.getByText('Something went wrong')).toBeInTheDocument();

    // Click try again button - this will reset the error state
    const tryAgainButton = screen.getByRole('button', { name: 'Try Again' });
    expect(tryAgainButton).toBeInTheDocument();

    await user.click(tryAgainButton);

    // After clicking try again, the error state should be reset
    // But since the component still throws an error, it will show the error again
    expect(screen.getByText('Something went wrong')).toBeInTheDocument();
  });
});
